Workbook

Sheet Hướng dẫn
A1: Kế hoạch đám cưới và mô phỏng hòa vốn
A3: Mục đích | B3: Trả lời hai câu hỏi: (1) tổng chi phí đám cưới đầy đủ là bao nhiêu, (2) cần bao nhiêu khách đến thì tiền mừng bù được chi phí, tức không lỗ.
A4: Cách dùng 4 bước | B4: Bước 1: vào sheet Giả định, chỉnh số khách mời, tỷ lệ đến, và đặc biệt mức mừng trung bình mỗi phong bì (ô vàng). Bước 2: vào sheet Chi phí, thay đơn giá bằng báo giá thật, tắt (0) hoặc thêm hạng mục. Bước 3: xem sheet Hòa vốn để đọc điểm hòa vốn, biểu đồ và bảng độ nhạy. Bước 4: thử vài kịch bản (khách ít, mừng thấp, tiệc rẻ hơn) và so sánh.
A5: Màu sắc | B5: Chữ xanh dương = ô bạn nhập. Chữ đen = công thức, đừng ghi đè. Chữ xanh lá = lấy số từ sheet khác. Nền vàng = giả định nhạy nhất.
A6: Số trong file là gì | B6: Giá bàn tiệc, VAT và phí phục vụ được lấy từ khảo sát TP.HCM 2026 (xem dòng Nguồn bên dưới) rồi cộng thêm buffer. Mọi hạng mục khác (trang trí, ảnh, váy, MC...) và mức mừng là ƯỚC TÍNH của Claude, vì không tìm được bảng giá hay thống kê TP.HCM đáng tin. Chưa có báo giá nhà hàng nào, nên bạn cần thay bằng báo giá thật trước khi ra quyết định.
A7: Nguồn khảo sát (TP.HCM) | B7: Phần lớn là trang quảng cáo của sảnh tiệc và đơn vị dịch vụ, đăng cách đây vài tháng, chưa kiểm chứng: - tonywedding.vn/bang-gia-nha-hang-tiec-cuoi (giá bàn theo sảnh) - asiana-plaza.com/bang-gia-nha-hang-tiec-cuoi-tphcm (4.5 đến 7.18 triệu/bàn) - capellagallery.com, whitewedding.vn, chungdoi.com (khung giá theo khu vực, mùa vụ, phụ thu 5% đến 10% cộng VAT) - Nghị quyết 204/2025/QH15: VAT 8% đến hết 31/12/2026 - vnexpress.net/an-cuoi-dat-do-4810963.html (ví dụ mức mừng 500,000 mỗi người) Không có khảo sát nào về mức mừng trung bình hay tỷ lệ khách đến ở TP.HCM.
A8: Hai điểm hòa vốn | B8: Toàn bộ chi phí: gồm cả tiệc, nghi lễ, váy, ảnh, nhẫn. Chỉ phần tiệc: chỉ so tiền mừng với chi phí tiệc. Điểm 'lần đầu không lỗ' có thể tụt lại thành lỗ ở số khách kế tiếp vì nhà hàng tính theo bàn nguyên (bước nhảy). Dùng điểm 'an toàn' để lập kế hoạch.
A9: Phương án không lỗ | B9: Sheet Phương án so sánh kịch bản hiện tại với 3 phương án dùng bản chi phí gọn (cột L ở sheet Chi phí). Dòng 'Mừng TB mỗi phong bì tối thiểu để không lỗ' cho biết mức mừng bạn cần thực sự nhận được. Nếu mức đó cao hơn mức mừng bạn tin là có thể, phương án chưa khả thi và bạn cần cắt thêm hoặc chuẩn bị nguồn bù.
A10: Mẹo kiểm soát | B10: 1) Gửi thiệp 4 đến 6 tuần trước, yêu cầu xác nhận (RSVP) ít nhất 10 đến 14 ngày trước ngày cưới. 2) Chốt số bàn chính thức với nhà hàng ở khoảng 90% số người đã xác nhận, phần còn lại dùng bàn dự phòng của sảnh. 3) Chia khách thành nhóm: nhóm thân (đến 95% đến 100%, mừng cao) và nhóm xã giao (đến khoảng 60% đến 70%, nhiều người chỉ gửi mừng). Nhập tỷ lệ đến bình quân đã gia quyền vào sheet Giả định. 4) Sheet Dòng tiền cho biết cần gom bao nhiêu tiền mặt trước ngày cưới.
A11: Lưu ý quan trọng | B11: 1) Tiền mừng cưới là khoản có tính hồi lễ (bạn sẽ đi mừng lại), nên 'không lỗ' ở đây chỉ là cân bằng dòng tiền. 2) Nếu cả hai họ cùng mở tiệc riêng, hãy chạy file này cho từng bên. 3) Mô hình giả định mức mừng đều. Thực tế khách thân mừng cao, đồng nghiệp mừng thấp: nên dùng trung bình từ sổ mừng thật. 4) Vàng cưới, trang sức hồi môn là tài sản giữ lại nên không tính vào chi phí. 5) Một số khoản phát sinh phụ thuộc hợp đồng (thuê sảnh, VAT, phụ thu giờ cao điểm): đọc kỹ báo giá.

Sheet Giả định
A1: Giả định chung của đám cưới
A2: Chữ xanh dương = ô bạn nhập. Ô nền vàng = giả định nhạy nhất, nên chỉnh theo thực tế của bạn trước tiên.
A3: A. Quy mô khách và số bàn
A4: Số khách mời | B4: 300 | C4: người | D4: Tổng số người bạn dự định mời (cả hai họ, bạn bè, đồng nghiệp).
A5: Tỷ lệ khách đến thực tế | B5: 0.85 | C5: % | D5: Thường 80% đến 90% so với số mời. Đám cưới ở quê hoặc mời đồng nghiệp xa thường thấp hơn.
A6: Số khách đến dự kiến | B6: =ROUND(B4*B5,0) -> 255 | C6: người | D6: Tự tính = khách mời x tỷ lệ đến. Đây là cần gạt chính của mô phỏng.
A7: Số khách mỗi bàn | B7: 10 | C7: người/bàn | D7: Chuẩn tiệc cưới Việt Nam là 10 người/bàn.
A8: Bàn dự phòng thêm | B8: 1 | C8: bàn | D8: Nhà hàng thường tính đủ bàn đã đặt, nên luôn nên dự phòng ít nhất 1 bàn cho khách phát sinh.
A9: Số bàn tối thiểu nhà hàng yêu cầu | B9: 15 | C9: bàn | D9: Ghi theo hợp đồng nhà hàng. Dưới mức này vẫn phải trả đủ. Nhập 0 nếu không có điều khoản này.
A10: Số bàn phải trả | B10: =MAX(B9,ROUNDUP(B6/B7,0)+B8) -> 27 | C10: bàn | D10: Tự tính = lớn hơn giữa bàn tối thiểu và (khách đến / khách mỗi bàn, làm tròn lên) + bàn dự phòng.
A12: B. Thuế, phụ thu và dự phòng
A13: VAT trên các khoản đánh dấu VAT = 1 | B13: 0.1 | C13: % | D13: VAT giảm còn 8% chỉ áp dụng đến 31/12/2026 (Nghị quyết 204/2025/QH15), và chưa xác nhận được dịch vụ tiệc có thuộc diện giảm không. Bạn chưa chốt ngày cưới nên Claude dùng 10% để thận trọng. Nếu cưới trước hết 2026 và hóa đơn ghi 8% thì đổi thành 0.08.
A14: Phí phục vụ (service charge) trên các khoản đánh dấu VAT = 1 | B14: 0.07 | C14: % | D14: Các nguồn khảo sát TP.HCM ghi phí phục vụ khoảng 5% đến 10%. Claude lấy 7% (giữa khoảng, thiên cao một chút). Nhập 0 nếu báo giá ghi đã gồm phí phục vụ.
A15: Tổng VAT và phí phục vụ | B15: =B13+B14 -> 0.17 | C15: % | D15: Tự tính. Dùng làm hệ số phụ thu trong toàn bộ mô hình.
A16: Quỹ dự phòng rủi ro (% tổng chi phí) | B16: 0.1 | C16: % | D16: Khuyến nghị tối thiểu 10% cho phát sinh ngày cưới (thêm bàn, đổi kế hoạch, tip, trang trí thêm).
A18: C. Nguồn thu từ tiền mừng cưới
A19: Số người trung bình mỗi phong bì | B19: 1.4 | C19: người/phong bì | D19: Vì nhiều cặp đôi và gia đình đi chung một phong bì. 1.0 nghĩa là mỗi người một phong bì.
A20: Mức mừng trung bình mỗi phong bì (khách đến dự) | B20: 500000 | C20: VND | D20: Theo yêu cầu của bạn: lấy mức thấp nhất, 500,000 mỗi phong bì (kịch bản xấu nhất). Không có thống kê TP.HCM: ví dụ cá nhân là 500,000 mỗi người khi dự tiệc, và khoảng 1,000,000 đến 4,000,000 cho tiệc nhà hàng, khách sạn (nguồn chung, không phải khảo sát). Đây là giả định quyết định lãi hay lỗ, thay bằng số thật khi có.
A21: Tỷ lệ người vắng mặt vẫn gửi tiền mừng | B21: 0.4 | C21: % | D21: Giả định của Claude. Khách xã giao, đồng nghiệp thường gửi mừng mà không dự tiệc. Nhập 0 nếu muốn tính thận trọng.
A22: Mức mừng trung bình mỗi phong bì gửi từ người vắng mặt | B22: 300000 | C22: VND | D22: Giả định của Claude, thấp nhất như khách dự. Ví dụ cá nhân ở TP.HCM: 300,000 khi không dự tiệc.
A23: Mừng từ người vắng mặt tính trên mỗi khách đến | B23: =(1-B5)/B5*B21*B22/B19 -> 15126.05 | C23: VND/người | D23: Tự tính. Người vắng = khách đến x (1 - tỷ lệ đến) / tỷ lệ đến. Khoản này không phát sinh biến phí tiệc nên thu thẳng vào bù chi phí cố định.
A24: Thu cố định khác | B24: 0 | C24: VND | D24: Ví dụ hỗ trợ của bố mẹ. Mặc định 0 để tính thận trọng.
A25: Tổng mừng trung bình mỗi khách đến | B25: =B20/B19+B23 -> 372268.91 | C25: VND/người | D25: Tự tính = mừng mỗi khách dự + mừng từ người vắng, tính trên mỗi khách đến.
A27: D. Mục tiêu (dùng cho công cụ đảo ngược ở sheet Hòa vốn)
A28: Ngân sách trần tổng chi phí | C28: VND | D28: Bạn chưa có số này nên để trống. Khi nhập, sheet Hòa vốn sẽ tính giá thực đơn tối đa mỗi bàn để không vượt trần.
A29: Mức lỗ chấp nhận được | B29: 0 | C29: VND | D29: 0 nghĩa là phải hòa vốn. Nhập số dương (ví dụ 30,000,000) nếu bạn chấp nhận bù một phần từ tiền của mình.

Sheet Chi phí
A1: Danh mục chi phí đám cưới (đầy đủ)
A2: Cách tính: Cố định = trả một lần. Theo bàn = đơn giá x số bàn. Theo khách = đơn giá x số khách đến. Cột Tính: 1 = đưa vào ngân sách, 0 = tắt. Cột VAT: 1 = chịu VAT/phụ thu. Mọi đơn giá là ước tính tham khảo của Claude cho tiệc cưới tầm trung ở đô thị, hãy thay bằng báo giá thật.
A3: Cột L: đơn giá của BẢN GỌN (tiệc tối giản) để sheet Phương án so sánh. Mặc định bằng giá đầy đủ nếu không cắt. Giá bản gọn là ước tính của Claude, bạn chỉnh theo thực tế. Riêng giá bàn tiệc không dùng cột này, được nhập trực tiếp ở từng phương án.
A4: STT | B4: Nhóm | C4: Hạng mục | D4: Cách tính | E4: Đơn giá (VND) | F4: Số lượng nhân | G4: VAT (1/0) | H4: Tính (1/0) | I4: Thành tiền kịch bản cơ sở (VND) | J4: Chi phí hiệu dụng mỗi đơn vị (cột phụ) | K4: Ghi chú / giả định | L4: Đơn giá BẢN GỌN (VND) | M4: Chi phí hiệu dụng bản gọn (cột phụ)
A5: 1 | B5: 1. Tiệc cưới | C5: Thực đơn tiệc trọn bàn (món ăn, đã gồm đồ uống) | D5: Theo bàn | E5: 7000000 | F5: 1 | G5: 1 | H5: 1 | I5: =H5*E5*F5*IF(D5="Cố định",1,IF(D5="Theo bàn",'Giả định'!$B$10,IF(D5="Theo khách",'Giả định'!$B$6,0))) -> 189000000 | J5: =E5*F5*H5 -> 7000000 | K5: Theo yêu cầu của bạn: giá bàn trung bình 7 triệu, hiểu là trọn bàn gồm cả đồ uống, chưa VAT và phí phục vụ. Khảo sát TP.HCM 2026 (trang quảng cáo sảnh): phổ thông 3.3 đến 4.5 triệu, Asiana Plaza 4.5 đến 7.18, khách sạn cao hơn. Biến số lớn nhất của ngân sách, thay bằng báo giá thật. | L5: 7000000 | M5: =L5*F5*H5 -> 7000000
A6: 2 | B6: 1. Tiệc cưới | C6: Đồ uống tính thêm (nếu báo giá chưa gồm) | D6: Theo bàn | E6: 0 | F6: 1 | G6: 1 | H6: 1 | I6: =H6*E6*F6*IF(D6="Cố định",1,IF(D6="Theo bàn",'Giả định'!$B$10,IF(D6="Theo khách",'Giả định'!$B$6,0))) -> 0 | J6: =E6*F6*H6 -> 0 | K6: Đang để 0 vì giá 7 triệu đã hiểu là gồm đồ uống. Nếu nhà hàng tính đồ uống riêng, nhập thêm (ví dụ 500,000 mỗi bàn). | L6: 0 | M6: =L6*F6*H6 -> 0
A7: 3 | B7: 1. Tiệc cưới | C7: Hoa và trang trí bàn tiệc | D7: Theo bàn | E7: 150000 | F7: 1 | G7: 0 | H7: 1 | I7: =H7*E7*F7*IF(D7="Cố định",1,IF(D7="Theo bàn",'Giả định'!$B$10,IF(D7="Theo khách",'Giả định'!$B$6,0))) -> 4050000 | J7: =E7*F7*H7 -> 150000 | K7: Bình hoa hoặc nến mỗi bàn. | L7: 100000 | M7: =L7*F7*H7 -> 100000
A8: 4 | B8: 1. Tiệc cưới | C8: Thuê sảnh / phí mặt bằng | D8: Cố định | E8: 5000000 | F8: 1 | G8: 1 | H8: 1 | I8: =H8*E8*F8*IF(D8="Cố định",1,IF(D8="Theo bàn",'Giả định'!$B$10,IF(D8="Theo khách",'Giả định'!$B$6,0))) -> 5000000 | J8: =E8*F8*H8 -> 5000000 | K8: Nhiều nơi miễn phí nếu đủ số bàn tối thiểu, khi đó nhập 0. | L8: 0 | M8: =L8*F8*H8 -> 0
A9: 5 | B9: 1. Tiệc cưới | C9: Trang trí sảnh: cổng hoa, backdrop, sân khấu, bàn gallery | D9: Cố định | E9: 20000000 | F9: 1 | G9: 0 | H9: 1 | I9: =H9*E9*F9*IF(D9="Cố định",1,IF(D9="Theo bàn",'Giả định'!$B$10,IF(D9="Theo khách",'Giả định'!$B$6,0))) -> 20000000 | J9: =E9*F9*H9 -> 20000000 | K9: Gói tầm trung 15 đến 30 triệu. Hoa tươi dễ vượt ngân sách nhất, hoa lụa hoặc hoa mix rẻ hơn nhiều. | L9: 10000000 | M9: =L9*F9*H9 -> 10000000
A10: 6 | B10: 1. Tiệc cưới | C10: MC, âm thanh, ánh sáng, màn hình LED | D10: Cố định | E10: 10000000 | F10: 1 | G10: 0 | H10: 1 | I10: =H10*E10*F10*IF(D10="Cố định",1,IF(D10="Theo bàn",'Giả định'!$B$10,IF(D10="Theo khách",'Giả định'!$B$6,0))) -> 10000000 | J10: =E10*F10*H10 -> 10000000 | L10: 6000000 | M10: =L10*F10*H10 -> 6000000
A11: 7 | B11: 1. Tiệc cưới | C11: Ca sĩ / ban nhạc / văn nghệ | D11: Cố định | E11: 5000000 | F11: 1 | G11: 0 | H11: 1 | I11: =H11*E11*F11*IF(D11="Cố định",1,IF(D11="Theo bàn",'Giả định'!$B$10,IF(D11="Theo khách",'Giả định'!$B$6,0))) -> 5000000 | J11: =E11*F11*H11 -> 5000000 | K11: Có thể bỏ nếu tiệc gọn. | L11: 0 | M11: =L11*F11*H11 -> 0
A12: 8 | B12: 1. Tiệc cưới | C12: Bánh cưới và tháp champagne | D12: Cố định | E12: 4000000 | F12: 1 | G12: 0 | H12: 1 | I12: =H12*E12*F12*IF(D12="Cố định",1,IF(D12="Theo bàn",'Giả định'!$B$10,IF(D12="Theo khách",'Giả định'!$B$6,0))) -> 4000000 | J12: =E12*F12*H12 -> 4000000 | L12: 2000000 | M12: =L12*F12*H12 -> 2000000
A13: 9 | B13: 1. Tiệc cưới | C13: Photobooth / khu check-in | D13: Cố định | E13: 3000000 | F13: 1 | G13: 0 | H13: 1 | I13: =H13*E13*F13*IF(D13="Cố định",1,IF(D13="Theo bàn",'Giả định'!$B$10,IF(D13="Theo khách",'Giả định'!$B$6,0))) -> 3000000 | J13: =E13*F13*H13 -> 3000000 | L13: 0 | M13: =L13*F13*H13 -> 0
A14: 10 | B14: 1. Tiệc cưới | C14: Hòm tiền mừng, sổ lưu bút, bảng tên bàn | D14: Cố định | E14: 500000 | F14: 1 | G14: 0 | H14: 1 | I14: =H14*E14*F14*IF(D14="Cố định",1,IF(D14="Theo bàn",'Giả định'!$B$10,IF(D14="Theo khách",'Giả định'!$B$6,0))) -> 500000 | J14: =E14*F14*H14 -> 500000 | L14: 300000 | M14: =L14*F14*H14 -> 300000
A15: 11 | B15: 1. Tiệc cưới | C15: Nhân sự lễ tân, điều phối ngày cưới | D15: Cố định | E15: 3000000 | F15: 1 | G15: 0 | H15: 1 | I15: =H15*E15*F15*IF(D15="Cố định",1,IF(D15="Theo bàn",'Giả định'!$B$10,IF(D15="Theo khách",'Giả định'!$B$6,0))) -> 3000000 | J15: =E15*F15*H15 -> 3000000 | K15: Tiền công người thân hoặc thuê ngoài. | L15: 1000000 | M15: =L15*F15*H15 -> 1000000
A16: 12 | B16: 1. Tiệc cưới | C16: Tiền bồi dưỡng: quản lý sảnh, phục vụ, tài xế, bảo vệ, thợ ảnh | D16: Cố định | E16: 2000000 | F16: 1 | G16: 0 | H16: 1 | I16: =H16*E16*F16*IF(D16="Cố định",1,IF(D16="Theo bàn",'Giả định'!$B$10,IF(D16="Theo khách",'Giả định'!$B$6,0))) -> 2000000 | J16: =E16*F16*H16 -> 2000000 | L16: 1500000 | M16: =L16*F16*H16 -> 1500000
A17: 13 | B17: 1. Tiệc cưới | C17: Quà cảm ơn khách (bánh, kẹo, quà nhỏ) | D17: Theo khách | E17: 25000 | F17: 1 | G17: 0 | H17: 1 | I17: =H17*E17*F17*IF(D17="Cố định",1,IF(D17="Theo bàn",'Giả định'!$B$10,IF(D17="Theo khách",'Giả định'!$B$6,0))) -> 6375000 | J17: =E17*F17*H17 -> 25000 | K17: Mỗi khách đến một phần. | L17: 15000 | M17: =L17*F17*H17 -> 15000
A18: 14 | B18: 1. Tiệc cưới | C18: Thiệp mời và phong bì in | D18: Theo khách | E18: 12000 | F18: 0.7 | G18: 0 | H18: 1 | I18: =H18*E18*F18*IF(D18="Cố định",1,IF(D18="Theo bàn",'Giả định'!$B$10,IF(D18="Theo khách",'Giả định'!$B$6,0))) -> 2142000 | J18: =E18*F18*H18 -> 8400 | K18: Số lượng nhân 0.7 nghĩa là khoảng 0.7 thiệp cho mỗi khách đến (một thiệp cho cả cặp hoặc gia đình, cộng thiệp thừa). | L18: 8000 | M18: =L18*F18*H18 -> 5600
A19: 15 | B19: 2. Lễ nghi | C19: Tráp và mâm quả ăn hỏi (bên mình) | D19: Cố định | E19: 15000000 | F19: 1 | G19: 0 | H19: 1 | I19: =H19*E19*F19*IF(D19="Cố định",1,IF(D19="Theo bàn",'Giả định'!$B$10,IF(D19="Theo khách",'Giả định'!$B$6,0))) -> 15000000 | J19: =E19*F19*H19 -> 15000000 | K19: Nếu nhà trai lo tráp thì đây là khoản bên gái chuẩn bị đáp lễ, chỉnh theo vai trò của bạn. | L19: 10000000 | M19: =L19*F19*H19 -> 10000000
A20: 16 | B20: 2. Lễ nghi | C20: Tiệc ăn hỏi / họ hàng thân (số bàn nhập ở Số lượng nhân) | D20: Cố định | E20: 3000000 | F20: 5 | G20: 1 | H20: 1 | I20: =H20*E20*F20*IF(D20="Cố định",1,IF(D20="Theo bàn",'Giả định'!$B$10,IF(D20="Theo khách",'Giả định'!$B$6,0))) -> 15000000 | J20: =E20*F20*H20 -> 15000000 | K20: 5 bàn x 3 triệu. Chỉnh số bàn ở cột Số lượng nhân. | L20: 1800000 | M20: =L20*F20*H20 -> 9000000
A21: 17 | B21: 2. Lễ nghi | C21: Trang trí nhà, cổng cưới, bàn thờ gia tiên | D21: Cố định | E21: 5000000 | F21: 1 | G21: 0 | H21: 1 | I21: =H21*E21*F21*IF(D21="Cố định",1,IF(D21="Theo bàn",'Giả định'!$B$10,IF(D21="Theo khách",'Giả định'!$B$6,0))) -> 5000000 | J21: =E21*F21*H21 -> 5000000 | L21: 2000000 | M21: =L21*F21*H21 -> 2000000
A22: 18 | B22: 2. Lễ nghi | C22: Xe hoa và xe rước dâu | D22: Cố định | E22: 4000000 | F22: 1 | G22: 0 | H22: 1 | I22: =H22*E22*F22*IF(D22="Cố định",1,IF(D22="Theo bàn",'Giả định'!$B$10,IF(D22="Theo khách",'Giả định'!$B$6,0))) -> 4000000 | J22: =E22*F22*H22 -> 4000000 | L22: 2000000 | M22: =L22*F22*H22 -> 2000000
A23: 19 | B23: 2. Lễ nghi | C23: Đội bưng quả, bao lì xì nghi lễ | D23: Cố định | E23: 3000000 | F23: 1 | G23: 0 | H23: 1 | I23: =H23*E23*F23*IF(D23="Cố định",1,IF(D23="Theo bàn",'Giả định'!$B$10,IF(D23="Theo khách",'Giả định'!$B$6,0))) -> 3000000 | J23: =E23*F23*H23 -> 3000000 | K23: Thường 6 đến 10 người, mỗi người một phong bì. | L23: 2000000 | M23: =L23*F23*H23 -> 2000000
A24: 20 | B24: 2. Lễ nghi | C24: Lễ lại mặt (hôm sau cưới) | D24: Cố định | E24: 4000000 | F24: 1 | G24: 0 | H24: 1 | I24: =H24*E24*F24*IF(D24="Cố định",1,IF(D24="Theo bàn",'Giả định'!$B$10,IF(D24="Theo khách",'Giả định'!$B$6,0))) -> 4000000 | J24: =E24*F24*H24 -> 4000000 | L24: 2000000 | M24: =L24*F24*H24 -> 2000000
A25: 21 | B25: 3. Trang phục và làm đẹp | C25: Váy cưới (thuê hoặc may) 2 đến 3 bộ | D25: Cố định | E25: 12000000 | F25: 1 | G25: 0 | H25: 1 | I25: =H25*E25*F25*IF(D25="Cố định",1,IF(D25="Theo bàn",'Giả định'!$B$10,IF(D25="Theo khách",'Giả định'!$B$6,0))) -> 12000000 | J25: =E25*F25*H25 -> 12000000 | L25: 6000000 | M25: =L25*F25*H25 -> 6000000
A26: 22 | B26: 3. Trang phục và làm đẹp | C26: Vest chú rể | D26: Cố định | E26: 4000000 | F26: 1 | G26: 0 | H26: 1 | I26: =H26*E26*F26*IF(D26="Cố định",1,IF(D26="Theo bàn",'Giả định'!$B$10,IF(D26="Theo khách",'Giả định'!$B$6,0))) -> 4000000 | J26: =E26*F26*H26 -> 4000000 | L26: 2000000 | M26: =L26*F26*H26 -> 2000000
A27: 23 | B27: 3. Trang phục và làm đẹp | C27: Áo dài gia đình hai bên | D27: Cố định | E27: 3000000 | F27: 1 | G27: 0 | H27: 1 | I27: =H27*E27*F27*IF(D27="Cố định",1,IF(D27="Theo bàn",'Giả định'!$B$10,IF(D27="Theo khách",'Giả định'!$B$6,0))) -> 3000000 | J27: =E27*F27*H27 -> 3000000 | L27: 1500000 | M27: =L27*F27*H27 -> 1500000
A28: 24 | B28: 3. Trang phục và làm đẹp | C28: Trang điểm và làm tóc cô dâu (ăn hỏi và ngày cưới) | D28: Cố định | E28: 6000000 | F28: 1 | G28: 0 | H28: 1 | I28: =H28*E28*F28*IF(D28="Cố định",1,IF(D28="Theo bàn",'Giả định'!$B$10,IF(D28="Theo khách",'Giả định'!$B$6,0))) -> 6000000 | J28: =E28*F28*H28 -> 6000000 | L28: 4000000 | M28: =L28*F28*H28 -> 4000000
A29: 25 | B29: 3. Trang phục và làm đẹp | C29: Trang điểm mẹ, phù dâu, phù rể | D29: Cố định | E29: 2500000 | F29: 1 | G29: 0 | H29: 1 | I29: =H29*E29*F29*IF(D29="Cố định",1,IF(D29="Theo bàn",'Giả định'!$B$10,IF(D29="Theo khách",'Giả định'!$B$6,0))) -> 2500000 | J29: =E29*F29*H29 -> 2500000 | L29: 1500000 | M29: =L29*F29*H29 -> 1500000
A30: 26 | B30: 3. Trang phục và làm đẹp | C30: Hoa cầm tay và hoa cài áo | D30: Cố định | E30: 1500000 | F30: 1 | G30: 0 | H30: 1 | I30: =H30*E30*F30*IF(D30="Cố định",1,IF(D30="Theo bàn",'Giả định'!$B$10,IF(D30="Theo khách",'Giả định'!$B$6,0))) -> 1500000 | J30: =E30*F30*H30 -> 1500000 | L30: 1000000 | M30: =L30*F30*H30 -> 1000000
A31: 27 | B31: 3. Trang phục và làm đẹp | C31: Phụ kiện: giày, voan, trang sức thuê | D31: Cố định | E31: 1500000 | F31: 1 | G31: 0 | H31: 1 | I31: =H31*E31*F31*IF(D31="Cố định",1,IF(D31="Theo bàn",'Giả định'!$B$10,IF(D31="Theo khách",'Giả định'!$B$6,0))) -> 1500000 | J31: =E31*F31*H31 -> 1500000 | L31: 800000 | M31: =L31*F31*H31 -> 800000
A32: 28 | B32: 4. Ảnh và video | C32: Chụp ảnh cưới (pre-wedding) và album | D32: Cố định | E32: 12000000 | F32: 1 | G32: 0 | H32: 1 | I32: =H32*E32*F32*IF(D32="Cố định",1,IF(D32="Theo bàn",'Giả định'!$B$10,IF(D32="Theo khách",'Giả định'!$B$6,0))) -> 12000000 | J32: =E32*F32*H32 -> 12000000 | L32: 6000000 | M32: =L32*F32*H32 -> 6000000
A33: 29 | B33: 4. Ảnh và video | C33: Ảnh phóng sự ngày cưới | D33: Cố định | E33: 8000000 | F33: 1 | G33: 0 | H33: 1 | I33: =H33*E33*F33*IF(D33="Cố định",1,IF(D33="Theo bàn",'Giả định'!$B$10,IF(D33="Theo khách",'Giả định'!$B$6,0))) -> 8000000 | J33: =E33*F33*H33 -> 8000000 | L33: 5000000 | M33: =L33*F33*H33 -> 5000000
A34: 30 | B34: 4. Ảnh và video | C34: Quay phim, flycam, video clip | D34: Cố định | E34: 8000000 | F34: 1 | G34: 0 | H34: 1 | I34: =H34*E34*F34*IF(D34="Cố định",1,IF(D34="Theo bàn",'Giả định'!$B$10,IF(D34="Theo khách",'Giả định'!$B$6,0))) -> 8000000 | J34: =E34*F34*H34 -> 8000000 | L34: 4000000 | M34: =L34*F34*H34 -> 4000000
A35: 31 | B35: 4. Ảnh và video | C35: In ảnh, khung ảnh treo tại tiệc | D35: Cố định | E35: 2000000 | F35: 1 | G35: 0 | H35: 1 | I35: =H35*E35*F35*IF(D35="Cố định",1,IF(D35="Theo bàn",'Giả định'!$B$10,IF(D35="Theo khách",'Giả định'!$B$6,0))) -> 2000000 | J35: =E35*F35*H35 -> 2000000 | L35: 1000000 | M35: =L35*F35*H35 -> 1000000
A36: 32 | B36: 5. Nhẫn và giấy tờ | C36: Nhẫn cưới | D36: Cố định | E36: 10000000 | F36: 1 | G36: 0 | H36: 1 | I36: =H36*E36*F36*IF(D36="Cố định",1,IF(D36="Theo bàn",'Giả định'!$B$10,IF(D36="Theo khách",'Giả định'!$B$6,0))) -> 10000000 | J36: =E36*F36*H36 -> 10000000 | K36: Vàng cưới và trang sức hồi môn là tài sản giữ lại, không tính là chi phí tiêu hao nên không đưa vào đây. | L36: 6000000 | M36: =L36*F36*H36 -> 6000000
A37: 33 | B37: 5. Nhẫn và giấy tờ | C37: Đăng ký kết hôn, khám sức khỏe, giấy tờ | D37: Cố định | E37: 1000000 | F37: 1 | G37: 0 | H37: 1 | I37: =H37*E37*F37*IF(D37="Cố định",1,IF(D37="Theo bàn",'Giả định'!$B$10,IF(D37="Theo khách",'Giả định'!$B$6,0))) -> 1000000 | J37: =E37*F37*H37 -> 1000000 | L37: 1000000 | M37: =L37*F37*H37 -> 1000000
A38: 34 | B38: 6. Vận hành và phát sinh | C38: Di chuyển và lưu trú cho người thân, khách xa | D38: Cố định | E38: 5000000 | F38: 1 | G38: 0 | H38: 1 | I38: =H38*E38*F38*IF(D38="Cố định",1,IF(D38="Theo bàn",'Giả định'!$B$10,IF(D38="Theo khách",'Giả định'!$B$6,0))) -> 5000000 | J38: =E38*F38*H38 -> 5000000 | L38: 3000000 | M38: =L38*F38*H38 -> 3000000
A39: 35 | B39: 6. Vận hành và phát sinh | C39: Quà và phong bì cảm ơn người giúp việc | D39: Cố định | E39: 2000000 | F39: 1 | G39: 0 | H39: 1 | I39: =H39*E39*F39*IF(D39="Cố định",1,IF(D39="Theo bàn",'Giả định'!$B$10,IF(D39="Theo khách",'Giả định'!$B$6,0))) -> 2000000 | J39: =E39*F39*H39 -> 2000000 | L39: 1000000 | M39: =L39*F39*H39 -> 1000000
A40: 36 | B40: 6. Vận hành và phát sinh | C40: Đồ ăn nhẹ, nước cho cô dâu chú rể và ekip trước giờ tiệc | D40: Cố định | E40: 1000000 | F40: 1 | G40: 0 | H40: 1 | I40: =H40*E40*F40*IF(D40="Cố định",1,IF(D40="Theo bàn",'Giả định'!$B$10,IF(D40="Theo khách",'Giả định'!$B$6,0))) -> 1000000 | J40: =E40*F40*H40 -> 1000000 | K40: Thường bị bỏ sót. | L40: 500000 | M40: =L40*F40*H40 -> 500000
...

Sheet Hòa vốn
A1: Mô phỏng hòa vốn: bao nhiêu khách đến thì không lỗ?
A2: Mọi số trên trang này tự cập nhật theo sheet Giả định và Chi phí. Lãi/lỗ = tiền mừng thu được trừ toàn bộ chi phí.
A4: 1. Kịch bản cơ sở
A5: Số khách mời | B5: ='Giả định'!$B$4 -> 300
A6: Số khách đến dự kiến | B6: ='Giả định'!$B$6 -> 255
A7: Số bàn phải trả | B7: ='Giả định'!$B$10 -> 27
A8: Tổng chi phí (VND) | B8: ='Chi phí'!I59 -> 459356700
A9: Doanh thu tiền mừng (VND) | B9: ='Chi phí'!I60 -> 94928571
A10: LÃI / (LỖ) toàn bộ (VND) | B10: =B9-B8 -> -3.6442813e+08
A11: Chi phí bình quân mỗi khách đến (VND) | B11: =IF(B6=0,0,B8/B6) -> 1801398.8
A12: Mừng bình quân mỗi khách đến, gồm mừng từ người vắng (VND) | B12: ='Giả định'!$B$20/'Giả định'!$B$19+'Giả định'!$B$23 -> 372268.91
A13: Lãi/(Lỗ) nếu chỉ tính phần tiệc (VND) | B13: =INDEX('Mô phỏng'!$G$5:$G$1005,B6+1) -> -2.2082313e+08
A15: 2. Điểm hòa vốn
A16: Chỉ tiêu | B16: Toàn bộ chi phí | C16: Chỉ phần tiệc
A17: Số khách ĐẾN tối thiểu, lần đầu không lỗ | B17: =IF(COUNT('Mô phỏng'!$H$5:$H$1005)=0,"Không đạt (trên 1,000)",MIN('Mô phỏng'!$H$5:$H$1005)) -> Không đạt (trên 1,000) | C17: =IF(COUNT('Mô phỏng'!$J$5:$J$1005)=0,"Không đạt (trên 1,000)",MIN('Mô phỏng'!$J$5:$J$1005)) -> Không đạt (trên 1,000)
A18: Số khách ĐẾN an toàn (từ mức này trở lên luôn không lỗ) | B18: =IF(COUNTIF('Mô phỏng'!$F$5:$F$1005,"<0")=0,0,IF(MAX('Mô phỏng'!$I$5:$I$1005)>=1000,"Không đạt (trên 1,000)",MAX('Mô phỏng'!$I$5:$I$1005)+1)) -> Không đạt (trên 1,000) | C18: =IF(COUNTIF('Mô phỏng'!$G$5:$G$1005,"<0")=0,0,IF(MAX('Mô phỏng'!$K$5:$K$1005)>=1000,"Không đạt (trên 1,000)",MAX('Mô phỏng'!$K$5:$K$1005)+1)) -> Không đạt (trên 1,000)
A19: Số khách MỜI tương ứng (theo tỷ lệ đến) | B19: =IF(ISNUMBER(B18),ROUNDUP(B18/'Giả định'!$B$5,0),"n/a") -> n/a | C19: =IF(ISNUMBER(C18),ROUNDUP(C18/'Giả định'!$B$5,0),"n/a") -> n/a
A20: Số bàn phải trả tại mức an toàn | B20: =IF(ISNUMBER(B18),INDEX('Mô phỏng'!$B$5:$B$1005,B18+1),"n/a") -> n/a | C20: =IF(ISNUMBER(C18),INDEX('Mô phỏng'!$B$5:$B$1005,C18+1),"n/a") -> n/a
A21: Mức mừng TB mỗi phong bì cần có để hòa vốn ở số khách cơ sở (VND) | B21: =IF(B6=0,0,(INDEX('Mô phỏng'!$D$5:$D$1005,B6+1)-'Giả định'!$B$24-B6*'Giả định'!$B$23)/(B6/'Giả định'!$B$19)) -> 2500781.9 | C21: =IF(B6=0,0,(INDEX('Mô phỏng'!$C$5:$C$1005,B6+1)-'Giả định'!$B$24-B6*'Giả định'!$B$23)/(B6/'Giả định'!$B$19)) -> 1712362.3
A22: Tương đương mừng TB mỗi khách đến (VND) | B22: =B21/'Giả định'!$B$19 -> 1786272.8 | C22: =C21/'Giả định'!$B$19 -> 1223115.9
A23: Đóng góp biên mỗi khách thêm: mừng trừ biến phí (VND) | B23: ='Giả định'!$B$20/'Giả định'!$B$19+'Giả định'!$B$23-(('Chi phí'!$D$77+'Giả định'!$B$15*'Chi phí'!$G$77)/'Giả định'!$B$7+'Chi phí'!$E$77+'Giả định'!$B$15*'Chi phí'!$H$77)*(1+'Giả định'!$B$16) -> -581871.09 | C23: ='Giả định'!$B$20/'Giả định'!$B$19+'Giả định'!$B$23-(('Chi phí'!$D$76+'Giả định'!$B$15*'Chi phí'!$G$76)/'Giả định'!$B$7+'Chi phí'!$E$76+'Giả định'!$B$15*'Chi phí'!$H$76)*(1+'Giả định'!$B$16) -> -581871.09
A24: Hòa vốn xấp xỉ theo công thức = chi phí cố định / đóng góp biên (kiểm chéo) | B24: =IF(B23<=0,"Không bao giờ hòa vốn",MAX(0,('Chi phí'!$C$77+'Giả định'!$B$15*'Chi phí'!$F$77+'Giả định'!$B$8*('Chi phí'!$D$77+'Giả định'!$B$15*'Chi phí'!$G$77))*(1+'Giả định'!$B$16)-'Giả định'!$B$24)/B23) -> Không bao giờ hòa vốn | C24: =IF(C23<=0,"Không bao giờ hòa vốn",MAX(0,('Chi phí'!$C$76+'Giả định'!$B$15*'Chi phí'!$F$76+'Giả định'!$B$8*('Chi phí'!$D$76+'Giả định'!$B$15*'Chi phí'!$G$76))*(1+'Giả định'!$B$16)-'Giả định'!$B$24)/C23) -> Không bao giờ hòa vốn
A25: Kiểm tra: chi phí cơ sở khớp giữa sheet Chi phí và Mô phỏng | B25: =IF(ABS(B8-INDEX('Mô phỏng'!$D$5:$D$1005,B6+1))<1,"OK","LỆCH") -> OK
A26: Nếu đóng góp biên bằng hoặc dưới 0, thêm khách không bao giờ bù được chi phí cố định, cần tăng mức mừng hoặc giảm chi phí mỗi bàn. Dòng 24 bỏ qua bàn tối thiểu nên có thể lệch nhẹ so với dòng 18.
A28: 3. Độ nhạy: Lãi/(Lỗ) TOÀN BỘ chi phí (VND). Xanh = không lỗ, đỏ = lỗ
A29: Khách đến (dọc) / Mừng TB mỗi phong bì (ngang) | B29: 500000 | C29: 700000 | D29: 900000 | E29: 1100000 | F29: 1300000 | G29: 1500000
A30: 100 | B30: =($A30/'Giả định'!$B$19*B$29+$A30*'Giả định'!$B$23+'Giả định'!$B$24)-INDEX('Mô phỏng'!$D$5:$D$1005,$A30+1) -> -3.0634711e+08 | C30: =($A30/'Giả định'!$B$19*C$29+$A30*'Giả định'!$B$23+'Giả định'!$B$24)-INDEX('Mô phỏng'!$D$5:$D$1005,$A30+1) -> -2.9206139e+08 | D30: =($A30/'Giả định'!$B$19*D$29+$A30*'Giả định'!$B$23+'Giả định'!$B$24)-INDEX('Mô phỏng'!$D$5:$D$1005,$A30+1) -> -2.7777568e+08 | E30: =($A30/'Giả định'!$B$19*E$29+$A30*'Giả định'!$B$23+'Giả định'!$B$24)-INDEX('Mô phỏng'!$D$5:$D$1005,$A30+1) -> -2.6348997e+08 | F30: =($A30/'Giả định'!$B$19*F$29+$A30*'Giả định'!$B$23+'Giả định'!$B$24)-INDEX('Mô phỏng'!$D$5:$D$1005,$A30+1) -> -2.4920425e+08 | G30: =($A30/'Giả định'!$B$19*G$29+$A30*'Giả định'!$B$23+'Giả định'!$B$24)-INDEX('Mô phỏng'!$D$5:$D$1005,$A30+1) -> -2.3491854e+08
A31: 150 | B31: =($A31/'Giả định'!$B$19*B$29+$A31*'Giả định'!$B$23+'Giả định'!$B$24)-INDEX('Mô phỏng'!$D$5:$D$1005,$A31+1) -> -2.9874466e+08 | C31: =($A31/'Giả định'!$B$19*C$29+$A31*'Giả định'!$B$23+'Giả định'!$B$24)-INDEX('Mô phỏng'!$D$5:$D$1005,$A31+1) -> -2.7731609e+08 | D31: =($A31/'Giả định'!$B$19*D$29+$A31*'Giả định'!$B$23+'Giả định'!$B$24)-INDEX('Mô phỏng'!$D$5:$D$1005,$A31+1) -> -2.5588752e+08 | E31: =($A31/'Giả định'!$B$19*E$29+$A31*'Giả định'!$B$23+'Giả định'!$B$24)-INDEX('Mô phỏng'!$D$5:$D$1005,$A31+1) -> -2.3445895e+08 | F31: =($A31/'Giả định'!$B$19*F$29+$A31*'Giả định'!$B$23+'Giả định'!$B$24)-INDEX('Mô phỏng'!$D$5:$D$1005,$A31+1) -> -2.1303038e+08 | G31: =($A31/'Giả định'!$B$19*G$29+$A31*'Giả định'!$B$23+'Giả định'!$B$24)-INDEX('Mô phỏng'!$D$5:$D$1005,$A31+1) -> -1.9160181e+08
A32: 200 | B32: =($A32/'Giả định'!$B$19*B$29+$A32*'Giả định'!$B$23+'Giả định'!$B$24)-INDEX('Mô phỏng'!$D$5:$D$1005,$A32+1) -> -3.2783822e+08 | C32: =($A32/'Giả định'!$B$19*C$29+$A32*'Giả định'!$B$23+'Giả định'!$B$24)-INDEX('Mô phỏng'!$D$5:$D$1005,$A32+1) -> -2.9926679e+08 | D32: =($A32/'Giả định'!$B$19*D$29+$A32*'Giả định'!$B$23+'Giả định'!$B$24)-INDEX('Mô phỏng'!$D$5:$D$1005,$A32+1) -> -2.7069536e+08 | E32: =($A32/'Giả định'!$B$19*E$29+$A32*'Giả định'!$B$23+'Giả định'!$B$24)-INDEX('Mô phỏng'!$D$5:$D$1005,$A32+1) -> -2.4212393e+08 | F32: =($A32/'Giả định'!$B$19*F$29+$A32*'Giả định'!$B$23+'Giả định'!$B$24)-INDEX('Mô phỏng'!$D$5:$D$1005,$A32+1) -> -2.135525e+08 | G32: =($A32/'Giả định'!$B$19*G$29+$A32*'Giả định'!$B$23+'Giả định'!$B$24)-INDEX('Mô phỏng'!$D$5:$D$1005,$A32+1) -> -1.8498108e+08
A33: 250 | B33: =($A33/'Giả định'!$B$19*B$29+$A33*'Giả định'!$B$23+'Giả định'!$B$24)-INDEX('Mô phỏng'!$D$5:$D$1005,$A33+1) -> -3.5693177e+08 | C33: =($A33/'Giả định'!$B$19*C$29+$A33*'Giả định'!$B$23+'Giả định'!$B$24)-INDEX('Mô phỏng'!$D$5:$D$1005,$A33+1) -> -3.2121749e+08 | D33: =($A33/'Giả định'!$B$19*D$29+$A33*'Giả định'!$B$23+'Giả định'!$B$24)-INDEX('Mô phỏng'!$D$5:$D$1005,$A33+1) -> -2.855032e+08 | E33: =($A33/'Giả định'!$B$19*E$29+$A33*'Giả định'!$B$23+'Giả định'!$B$24)-INDEX('Mô phỏng'!$D$5:$D$1005,$A33+1) -> -2.4978892e+08 | F33: =($A33/'Giả định'!$B$19*F$29+$A33*'Giả định'!$B$23+'Giả định'!$B$24)-INDEX('Mô phỏng'!$D$5:$D$1005,$A33+1) -> -2.1407463e+08 | G33: =($A33/'Giả định'!$B$19*G$29+$A33*'Giả định'!$B$23+'Giả định'!$B$24)-INDEX('Mô phỏng'!$D$5:$D$1005,$A33+1) -> -1.7836034e+08
A34: 300 | B34: =($A34/'Giả định'!$B$19*B$29+$A34*'Giả định'!$B$23+'Giả định'!$B$24)-INDEX('Mô phỏng'!$D$5:$D$1005,$A34+1) -> -3.8602533e+08 | C34: =($A34/'Giả định'!$B$19*C$29+$A34*'Giả định'!$B$23+'Giả định'!$B$24)-INDEX('Mô phỏng'!$D$5:$D$1005,$A34+1) -> -3.4316818e+08 | D34: =($A34/'Giả định'!$B$19*D$29+$A34*'Giả định'!$B$23+'Giả định'!$B$24)-INDEX('Mô phỏng'!$D$5:$D$1005,$A34+1) -> -3.0031104e+08 | E34: =($A34/'Giả định'!$B$19*E$29+$A34*'Giả định'!$B$23+'Giả định'!$B$24)-INDEX('Mô phỏng'!$D$5:$D$1005,$A34+1) -> -2.574539e+08 | F34: =($A34/'Giả định'!$B$19*F$29+$A34*'Giả định'!$B$23+'Giả định'!$B$24)-INDEX('Mô phỏng'!$D$5:$D$1005,$A34+1) -> -2.1459676e+08 | G34: =($A34/'Giả định'!$B$19*G$29+$A34*'Giả định'!$B$23+'Giả định'!$B$24)-INDEX('Mô phỏng'!$D$5:$D$1005,$A34+1) -> -1.7173961e+08
A35: 350 | B35: =($A35/'Giả định'!$B$19*B$29+$A35*'Giả định'!$B$23+'Giả định'!$B$24)-INDEX('Mô phỏng'!$D$5:$D$1005,$A35+1) -> -4.1511888e+08 | C35: =($A35/'Giả định'!$B$19*C$29+$A35*'Giả định'!$B$23+'Giả định'!$B$24)-INDEX('Mô phỏng'!$D$5:$D$1005,$A35+1) -> -3.6511888e+08 | D35: =($A35/'Giả định'!$B$19*D$29+$A35*'Giả định'!$B$23+'Giả định'!$B$24)-INDEX('Mô phỏng'!$D$5:$D$1005,$A35+1) -> -3.1511888e+08 | E35: =($A35/'Giả định'!$B$19*E$29+$A35*'Giả định'!$B$23+'Giả định'!$B$24)-INDEX('Mô phỏng'!$D$5:$D$1005,$A35+1) -> -2.6511888e+08 | F35: =($A35/'Giả định'!$B$19*F$29+$A35*'Giả định'!$B$23+'Giả định'!$B$24)-INDEX('Mô phỏng'!$D$5:$D$1005,$A35+1) -> -2.1511888e+08 | G35: =($A35/'Giả định'!$B$19*G$29+$A35*'Giả định'!$B$23+'Giả định'!$B$24)-INDEX('Mô phỏng'!$D$5:$D$1005,$A35+1) -> -1.6511888e+08
A36: 400 | B36: =($A36/'Giả định'!$B$19*B$29+$A36*'Giả định'!$B$23+'Giả định'!$B$24)-INDEX('Mô phỏng'!$D$5:$D$1005,$A36+1) -> -4.4421244e+08 | C36: =($A36/'Giả định'!$B$19*C$29+$A36*'Giả định'!$B$23+'Giả định'!$B$24)-INDEX('Mô phỏng'!$D$5:$D$1005,$A36+1) -> -3.8706958e+08 | D36: =($A36/'Giả định'!$B$19*D$29+$A36*'Giả định'!$B$23+'Giả định'!$B$24)-INDEX('Mô phỏng'!$D$5:$D$1005,$A36+1) -> -3.2992672e+08 | E36: =($A36/'Giả định'!$B$19*E$29+$A36*'Giả định'!$B$23+'Giả định'!$B$24)-INDEX('Mô phỏng'!$D$5:$D$1005,$A36+1) -> -2.7278387e+08 | F36: =($A36/'Giả định'!$B$19*F$29+$A36*'Giả định'!$B$23+'Giả định'!$B$24)-INDEX('Mô phỏng'!$D$5:$D$1005,$A36+1) -> -2.1564101e+08 | G36: =($A36/'Giả định'!$B$19*G$29+$A36*'Giả định'!$B$23+'Giả định'!$B$24)-INDEX('Mô phỏng'!$D$5:$D$1005,$A36+1) -> -1.5849815e+08
A37: 450 | B37: =($A37/'Giả định'!$B$19*B$29+$A37*'Giả định'!$B$23+'Giả định'!$B$24)-INDEX('Mô phỏng'!$D$5:$D$1005,$A37+1) -> -4.7330599e+08 | C37: =($A37/'Giả định'!$B$19*C$29+$A37*'Giả định'!$B$23+'Giả định'!$B$24)-INDEX('Mô phỏng'!$D$5:$D$1005,$A37+1) -> -4.0902028e+08 | D37: =($A37/'Giả định'!$B$19*D$29+$A37*'Giả định'!$B$23+'Giả định'!$B$24)-INDEX('Mô phỏng'!$D$5:$D$1005,$A37+1) -> -3.4473456e+08 | E37: =($A37/'Giả định'!$B$19*E$29+$A37*'Giả định'!$B$23+'Giả định'!$B$24)-INDEX('Mô phỏng'!$D$5:$D$1005,$A37+1) -> -2.8044885e+08 | F37: =($A37/'Giả định'!$B$19*F$29+$A37*'Giả định'!$B$23+'Giả định'!$B$24)-INDEX('Mô phỏng'!$D$5:$D$1005,$A37+1) -> -2.1616313e+08 | G37: =($A37/'Giả định'!$B$19*G$29+$A37*'Giả định'!$B$23+'Giả định'!$B$24)-INDEX('Mô phỏng'!$D$5:$D$1005,$A37+1) -> -1.5187742e+08
A38: 500 | B38: =($A38/'Giả định'!$B$19*B$29+$A38*'Giả định'!$B$23+'Giả định'!$B$24)-INDEX('Mô phỏng'!$D$5:$D$1005,$A38+1) -> -5.0239955e+08 | C38: =($A38/'Giả định'!$B$19*C$29+$A38*'Giả định'!$B$23+'Giả định'!$B$24)-INDEX('Mô phỏng'!$D$5:$D$1005,$A38+1) -> -4.3097097e+08 | D38: =($A38/'Giả định'!$B$19*D$29+$A38*'Giả định'!$B$23+'Giả định'!$B$24)-INDEX('Mô phỏng'!$D$5:$D$1005,$A38+1) -> -3.595424e+08 | E38: =($A38/'Giả định'!$B$19*E$29+$A38*'Giả định'!$B$23+'Giả định'!$B$24)-INDEX('Mô phỏng'!$D$5:$D$1005,$A38+1) -> -2.8811383e+08 | F38: =($A38/'Giả định'!$B$19*F$29+$A38*'Giả định'!$B$23+'Giả định'!$B$24)-INDEX('Mô phỏng'!$D$5:$D$1005,$A38+1) -> -2.1668526e+08 | G38: =($A38/'Giả định'!$B$19*G$29+$A38*'Giả định'!$B$23+'Giả định'!$B$24)-INDEX('Mô phỏng'!$D$5:$D$1005,$A38+1) -> -1.4525669e+08
A39: 550 | B39: =($A39/'Giả định'!$B$19*B$29+$A39*'Giả định'!$B$23+'Giả định'!$B$24)-INDEX('Mô phỏng'!$D$5:$D$1005,$A39+1) -> -5.314931e+08 | C39: =($A39/'Giả định'!$B$19*C$29+$A39*'Giả định'!$B$23+'Giả định'!$B$24)-INDEX('Mô phỏng'!$D$5:$D$1005,$A39+1) -> -4.5292167e+08 | D39: =($A39/'Giả định'!$B$19*D$29+$A39*'Giả định'!$B$23+'Giả định'!$B$24)-INDEX('Mô phỏng'!$D$5:$D$1005,$A39+1) -> -3.7435024e+08 | E39: =($A39/'Giả định'!$B$19*E$29+$A39*'Giả định'!$B$23+'Giả định'!$B$24)-INDEX('Mô phỏng'!$D$5:$D$1005,$A39+1) -> -2.9577882e+08 | F39: =($A39/'Giả định'!$B$19*F$29+$A39*'Giả định'!$B$23+'Giả định'!$B$24)-INDEX('Mô phỏng'!$D$5:$D$1005,$A39+1) -> -2.1720739e+08 | G39: =($A39/'Giả định'!$B$19*G$29+$A39*'Giả định'!$B$23+'Giả định'!$B$24)-INDEX('Mô phỏng'!$D$5:$D$1005,$A39+1) -> -1.3863596e+08
A40: 600 | B40: =($A40/'Giả định'!$B$19*B$29+$A40*'Giả định'!$B$23+'Giả định'!$B$24)-INDEX('Mô phỏng'!$D$5:$D$1005,$A40+1) -> -5.6058666e+08 | C40: =($A40/'Giả định'!$B$19*C$29+$A40*'Giả định'!$B$23+'Giả định'!$B$24)-INDEX('Mô phỏng'!$D$5:$D$1005,$A40+1) -> -4.7487237e+08 | D40: =($A40/'Giả định'!$B$19*D$29+$A40*'Giả định'!$B$23+'Giả định'!$B$24)-INDEX('Mô phỏng'!$D$5:$D$1005,$A40+1) -> -3.8915808e+08 | E40: =($A40/'Giả định'!$B$19*E$29+$A40*'Giả định'!$B$23+'Giả định'!$B$24)-INDEX('Mô phỏng'!$D$5:$D$1005,$A40+1) -> -3.034438e+08 | F40: =($A40/'Giả định'!$B$19*F$29+$A40*'Giả định'!$B$23+'Giả định'!$B$24)-INDEX('Mô phỏng'!$D$5:$D$1005,$A40+1) -> -2.1772951e+08 | G40: =($A40/'Giả định'!$B$19*G$29+$A40*'Giả định'!$B$23+'Giả định'!$B$24)-INDEX('Mô phỏng'!$D$5:$D$1005,$A40+1) -> -1.3201523e+08
A42: 4. Độ nhạy: Lãi/(Lỗ) chỉ PHẦN TIỆC (VND), chưa tính váy, ảnh, nghi lễ
A43: Khách đến (dọc) / Mừng TB mỗi phong bì (ngang) | B43: 500000 | C43: 700000 | D43: 900000 | E43: 1100000 | F43: 1300000 | G43: 1500000
A44: 100 | B44: =($A44/'Giả định'!$B$19*B$43+$A44*'Giả định'!$B$23+'Giả định'!$B$24)-INDEX('Mô phỏng'!$C$5:$C$1005,$A44+1) -> -1.6274211e+08 | C44: =($A44/'Giả định'!$B$19*C$43+$A44*'Giả định'!$B$23+'Giả định'!$B$24)-INDEX('Mô phỏng'!$C$5:$C$1005,$A44+1) -> -1.4845639e+08 | D44: =($A44/'Giả định'!$B$19*D$43+$A44*'Giả định'!$B$23+'Giả định'!$B$24)-INDEX('Mô phỏng'!$C$5:$C$1005,$A44+1) -> -1.3417068e+08 | E44: =($A44/'Giả định'!$B$19*E$43+$A44*'Giả định'!$B$23+'Giả định'!$B$24)-INDEX('Mô phỏng'!$C$5:$C$1005,$A44+1) -> -1.1988497e+08 | F44: =($A44/'Giả định'!$B$19*F$43+$A44*'Giả định'!$B$23+'Giả định'!$B$24)-INDEX('Mô phỏng'!$C$5:$C$1005,$A44+1) -> -1.0559925e+08 | G44: =($A44/'Giả định'!$B$19*G$43+$A44*'Giả định'!$B$23+'Giả định'!$B$24)-INDEX('Mô phỏng'!$C$5:$C$1005,$A44+1) -> -91313538
...

Sheet Dòng tiền
A1: Dòng tiền: cần sẵn bao nhiêu tiền mặt trước khi chạm phong bì?
A2: Chi phí phải trả trước, tiền mừng chỉ về cuối tiệc. Chỉnh tỷ lệ các mốc theo hợp đồng thật. Tỷ lệ là giả định của Claude, thay bằng điều khoản cọc của nhà hàng và nhà cung cấp.
A4: Mốc thanh toán | B4: Thời điểm | C4: % tổng chi phí | D4: Số tiền (VND) | E4: Lũy kế (VND) | F4: Trả trước khi thu phong bì (1/0)
A5: Cọc giữ sảnh | B5: 6 đến 9 tháng trước | C5: 0.1 | D5: =C5*'Chi phí'!$I$59 -> 45935670 | E5: =D5 -> 45935670 | F5: 1
A6: Cọc thử món, trang trí, trang phục, ảnh | B6: 1 đến 2 tháng trước | C6: 0.3 | D6: =C6*'Chi phí'!$I$59 -> 137807010 | E6: =E5+D6 -> 183742680 | F6: 1
A7: Thanh toán ảnh, thiệp, váy, nghi lễ, tiền bồi dưỡng | B7: 1 tuần trước đến ngày cưới | C7: 0.25 | D7: =C7*'Chi phí'!$I$59 -> 114839175 | E7: =E6+D7 -> 298581855 | F7: 1
A8: Quyết toán tiệc sau khi thu phong bì | B8: Cuối tiệc hoặc ngay sau tiệc | C8: 0.35 | D8: =C8*'Chi phí'!$I$59 -> 160774845 | E8: =E7+D8 -> 459356700 | F8: 0
A9: Tổng | C9: =SUM(C5:C8) -> 1 | D9: =SUM(D5:D8) -> 459356700 | E9: =IF(ABS(C9-1)<0.0001,"OK: tổng = 100%","LỆCH: tổng tỷ lệ phải bằng 100%") -> OK: tổng = 100%
A11: Kết quả
A12: Tiền mặt phải có sẵn trước khi chạm phong bì (VND) | B12: =SUMPRODUCT(D5:D8,F5:F8) -> 298581855
A13: Tỷ lệ trên tổng chi phí | B13: =IF(D9=0,0,B12/D9) -> 0.65
A14: Khoản phải quyết toán sau khi thu phong bì (VND) | B14: =D9-B12 -> 160774845
A15: Tiền mừng dự kiến thu được (VND) | B15: ='Chi phí'!$I$60 -> 94928571
A16: Tiền mặt còn lại sau quyết toán, chưa hoàn lại phần đã trả trước (VND) | B16: =B15-B14 -> -65846274
A17: Lãi/(Lỗ) cuối cùng (VND) | B17: =B15-D9 -> -3.6442813e+08
A19: Cách đọc: dòng 12 là vốn tự có bạn phải gom trước, không được dựa vào tiền mừng. Nên có sẵn khoảng 60% đến 70% tổng chi phí và tránh vay thẻ tín dụng lãi cao để xoay vòng tiền cọc. Dòng 16 dương nghĩa là tiền mừng đủ trả phần quyết toán cuối, nhưng phần đã ứng trước chỉ được bù khi lãi/lỗ cuối (dòng 17) không âm.

Sheet Phương án
A1: Phương án để KHÔNG LỖ
A2: Cột B là kịch bản hiện tại theo sheet Giả định. Cột C đến E là các phương án bạn chỉnh (chữ xanh). Các dòng 'tối thiểu / tối đa' tính ngược: đó là điều kiện cần để P/L bằng hoặc cao hơn mức lỗ chấp nhận ở sheet Giả định.
A4: Tham số | B4: Hiện tại (theo Giả định) | C4: Phương án A | D4: Phương án B | E4: Phương án C
A5: Tên phương án | B5: Theo Giả định và Chi phí | C5: Tiệc gọn, sảnh phổ thông 4,2 triệu/bàn | D5: Tiệc gọn, sảnh rẻ 3,3 triệu/bàn | E5: Giữ bàn 7 triệu, chỉ cắt cho gọn
A6: Bản chi phí (1 = đầy đủ, 2 = gọn) | B6: 1 | C6: 2 | D6: 2 | E6: 2
A7: Số khách mời | B7: ='Giả định'!$B$4 -> 300 | C7: 300 | D7: 300 | E7: 300
A8: Tỷ lệ khách đến | B8: ='Giả định'!$B$5 -> 0.85 | C8: ='Giả định'!$B$5 -> 0.85 | D8: ='Giả định'!$B$5 -> 0.85 | E8: ='Giả định'!$B$5 -> 0.85
A9: Số khách đến | B9: =ROUND(B7*B8,0) -> 255 | C9: =ROUND(C7*C8,0) -> 255 | D9: =ROUND(D7*D8,0) -> 255 | E9: =ROUND(E7*E8,0) -> 255
A10: Giá bàn trọn gói (VND/bàn, chưa VAT và phí phục vụ) | B10: ='Chi phí'!$E$5*'Chi phí'!$F$5+'Chi phí'!$E$6*'Chi phí'!$F$6 -> 7000000 | C10: 4200000 | D10: 3300000 | E10: 7000000
A11: Số người mỗi phong bì | B11: ='Giả định'!$B$19 -> 1.4 | C11: ='Giả định'!$B$19 -> 1.4 | D11: ='Giả định'!$B$19 -> 1.4 | E11: ='Giả định'!$B$19 -> 1.4
A12: Mừng trung bình mỗi phong bì (VND) | B12: ='Giả định'!$B$20 -> 500000 | C12: 1450000 | D12: 1300000 | E12: 2100000
A13: Số bàn phải trả | B13: =MAX('Giả định'!$B$9,ROUNDUP(B9/'Giả định'!$B$7,0)+'Giả định'!$B$8) -> 27 | C13: =MAX('Giả định'!$B$9,ROUNDUP(C9/'Giả định'!$B$7,0)+'Giả định'!$B$8) -> 27 | D13: =MAX('Giả định'!$B$9,ROUNDUP(D9/'Giả định'!$B$7,0)+'Giả định'!$B$8) -> 27 | E13: =MAX('Giả định'!$B$9,ROUNDUP(E9/'Giả định'!$B$7,0)+'Giả định'!$B$8) -> 27
A15: Kết quả
A16: Tổng chi phí (VND) | B16: =(B29+B30*B13+B31*B9+'Giả định'!$B$15*(B32+B33*B13+B34*B9))*(1+'Giả định'!$B$16) -> 459356700 | C16: =(C29+C30*C13+C31*C9+'Giả định'!$B$15*(C32+C33*C13+C34*C9))*(1+'Giả định'!$B$16) -> 259007100 | D16: =(D29+D30*D13+D31*D9+'Giả định'!$B$15*(D32+D33*D13+D34*D9))*(1+'Giả định'!$B$16) -> 227733000 | E16: =(E29+E30*E13+E31*E9+'Giả định'!$B$15*(E32+E33*E13+E34*E9))*(1+'Giả định'!$B$16) -> 356304300
A17: Doanh thu tiền mừng (VND) | B17: =B9*(B12/B11+B35)+'Giả định'!$B$24 -> 94928571 | C17: =C9*(C12/C11+C35)+'Giả định'!$B$24 -> 2.6796429e+08 | D17: =D9*(D12/D11+D35)+'Giả định'!$B$24 -> 2.4064286e+08 | E17: =E9*(E12/E11+E35)+'Giả định'!$B$24 -> 3.8635714e+08
A18: LÃI / (LỖ) (VND) | B18: =B17-B16 -> -3.6442813e+08 | C18: =C17-C16 -> 8957185.7 | D18: =D17-D16 -> 12909857 | E18: =E17-E16 -> 30052843
A19: Kết luận | B19: =IF(B18+'Giả định'!$B$29>=0,"KHÔNG LỖ","LỖ "&ROUND(-(B18+'Giả định'!$B$29)/1000000,0)&" triệu") -> LỖ 364 triệu | C19: =IF(C18+'Giả định'!$B$29>=0,"KHÔNG LỖ","LỖ "&ROUND(-(C18+'Giả định'!$B$29)/1000000,0)&" triệu") -> KHÔNG LỖ | D19: =IF(D18+'Giả định'!$B$29>=0,"KHÔNG LỖ","LỖ "&ROUND(-(D18+'Giả định'!$B$29)/1000000,0)&" triệu") -> KHÔNG LỖ | E19: =IF(E18+'Giả định'!$B$29>=0,"KHÔNG LỖ","LỖ "&ROUND(-(E18+'Giả định'!$B$29)/1000000,0)&" triệu") -> KHÔNG LỖ
A20: Đóng góp biên mỗi khách thêm: mừng trừ biến phí (VND) | B20: =B12/B11+B35-((B30+'Giả định'!$B$15*B33)/'Giả định'!$B$7+B31+'Giả định'!$B$15*B34)*(1+'Giả định'!$B$16) -> -581871.09 | C20: =C12/C11+C35-((C30+'Giả định'!$B$15*C33)/'Giả định'!$B$7+C31+'Giả định'!$B$15*C34)*(1+'Giả định'!$B$16) -> 476640.34 | D20: =D12/D11+D35-((D30+'Giả định'!$B$15*D33)/'Giả định'!$B$7+D31+'Giả định'!$B$15*D34)*(1+'Giả định'!$B$16) -> 485327.48 | E20: =E12/E11+E35-((E30+'Giả định'!$B$15*E33)/'Giả định'!$B$7+E31+'Giả định'!$B$15*E34)*(1+'Giả định'!$B$16) -> 580566.05
A21: Chi phí cố định hiệu dụng, đã gồm VAT, dự phòng, bàn dự phòng (VND) | B21: =(B29+'Giả định'!$B$15*B32+'Giả định'!$B$8*(B30+'Giả định'!$B$15*B33))*(1+'Giả định'!$B$16) -> 211464000 | C21: =(C29+'Giả định'!$B$15*C32+'Giả định'!$B$8*(C30+'Giả định'!$B$15*C33))*(1+'Giả định'!$B$16) -> 109828400 | D21: =(D29+'Giả định'!$B$15*D32+'Giả định'!$B$8*(D30+'Giả định'!$B$15*D33))*(1+'Giả định'!$B$16) -> 108670100 | E21: =(E29+'Giả định'!$B$15*E32+'Giả định'!$B$8*(E30+'Giả định'!$B$15*E33))*(1+'Giả định'!$B$16) -> 113432000
A23: Tính ngược: điều kiện cần để không lỗ (giữ nguyên các tham số khác)
A24: Mừng TB mỗi phong bì TỐI THIỂU để không lỗ (VND) | B24: =IF(B9=0,0,(B16-'Giả định'!$B$29-'Giả định'!$B$24-B9*B35)*B11/B9) -> 2500781.9 | C24: =IF(C9=0,0,(C16-'Giả định'!$B$29-'Giả định'!$B$24-C9*C35)*C11/C9) -> 1400823.3 | D24: =IF(D9=0,0,(D16-'Giả định'!$B$29-'Giả định'!$B$24-D9*D35)*D11/D9) -> 1229122.4 | E24: =IF(E9=0,0,(E16-'Giả định'!$B$29-'Giả định'!$B$24-E9*E35)*E11/E9) -> 1935004
A25: Giá bàn TỐI ĐA để không lỗ (VND, số âm = không khả thi) | B25: =B10+(B18+'Giả định'!$B$29)/(B13*(1+'Giả định'!$B$15)*(1+'Giả định'!$B$16)) -> -3487442.2 | C25: =C10+(C18+'Giả định'!$B$29)/(C13*(1+'Giả định'!$B$15)*(1+'Giả định'!$B$16)) -> 4457768.2 | D25: =D10+(D18+'Giả định'!$B$29)/(D13*(1+'Giả định'!$B$15)*(1+'Giả định'!$B$16)) -> 3671517.4 | E25: =E10+(E18+'Giả định'!$B$29)/(E13*(1+'Giả định'!$B$15)*(1+'Giả định'!$B$16)) -> 7864854.9
A26: Số khách đến xấp xỉ để hòa vốn (cố định hiệu dụng / đóng góp biên) | B26: =IF(B20<=0,"Không bao giờ",MAX(0,B21-'Giả định'!$B$24)/B20) -> Không bao giờ | C26: =IF(C20<=0,"Không bao giờ",MAX(0,C21-'Giả định'!$B$24)/C20) -> 230.42196 | D26: =IF(D20<=0,"Không bao giờ",MAX(0,D21-'Giả định'!$B$24)/D20) -> 223.91087 | E26: =IF(E20<=0,"Không bao giờ",MAX(0,E21-'Giả định'!$B$24)/E20) -> 195.38173
A28: Tham số tính toán (cột phụ, không cần chỉnh)
A29: Chi phí cố định (VND) | B29: =CHOOSE(B$6,'Chi phí'!$C$77,'Chi phí'!$C$78) -> 180500000 | C29: =CHOOSE(C$6,'Chi phí'!$C$77,'Chi phí'!$C$78) -> 93300000 | D29: =CHOOSE(D$6,'Chi phí'!$C$77,'Chi phí'!$C$78) -> 93300000 | E29: =CHOOSE(E$6,'Chi phí'!$C$77,'Chi phí'!$C$78) -> 93300000
A30: Giá bàn mỗi bàn, gồm các khoản theo bàn khác (VND) | B30: =CHOOSE(B$6,'Chi phí'!$D$77,'Chi phí'!$D$78)-('Chi phí'!$J$5+'Chi phí'!$J$6)+B10 -> 7150000 | C30: =CHOOSE(C$6,'Chi phí'!$D$77,'Chi phí'!$D$78)-('Chi phí'!$J$5+'Chi phí'!$J$6)+C10 -> 4300000 | D30: =CHOOSE(D$6,'Chi phí'!$D$77,'Chi phí'!$D$78)-('Chi phí'!$J$5+'Chi phí'!$J$6)+D10 -> 3400000 | E30: =CHOOSE(E$6,'Chi phí'!$D$77,'Chi phí'!$D$78)-('Chi phí'!$J$5+'Chi phí'!$J$6)+E10 -> 7100000
A31: Chi phí theo khách (VND/khách) | B31: =CHOOSE(B$6,'Chi phí'!$E$77,'Chi phí'!$E$78) -> 33400 | C31: =CHOOSE(C$6,'Chi phí'!$E$77,'Chi phí'!$E$78) -> 20600 | D31: =CHOOSE(D$6,'Chi phí'!$E$77,'Chi phí'!$E$78) -> 20600 | E31: =CHOOSE(E$6,'Chi phí'!$E$77,'Chi phí'!$E$78) -> 20600
A32: Cố định chịu VAT (VND) | B32: =CHOOSE(B$6,'Chi phí'!$F$77,'Chi phí'!$F$78) -> 20000000 | C32: =CHOOSE(C$6,'Chi phí'!$F$77,'Chi phí'!$F$78) -> 9000000 | D32: =CHOOSE(D$6,'Chi phí'!$F$77,'Chi phí'!$F$78) -> 9000000 | E32: =CHOOSE(E$6,'Chi phí'!$F$77,'Chi phí'!$F$78) -> 9000000
A33: Theo bàn chịu VAT (VND/bàn) | B33: =CHOOSE(B$6,'Chi phí'!$G$77,'Chi phí'!$G$78)-('Chi phí'!$J$5*'Chi phí'!$G$5+'Chi phí'!$J$6*'Chi phí'!$G$6)+B10 -> 7000000 | C33: =CHOOSE(C$6,'Chi phí'!$G$77,'Chi phí'!$G$78)-('Chi phí'!$J$5*'Chi phí'!$G$5+'Chi phí'!$J$6*'Chi phí'!$G$6)+C10 -> 4200000 | D33: =CHOOSE(D$6,'Chi phí'!$G$77,'Chi phí'!$G$78)-('Chi phí'!$J$5*'Chi phí'!$G$5+'Chi phí'!$J$6*'Chi phí'!$G$6)+D10 -> 3300000 | E33: =CHOOSE(E$6,'Chi phí'!$G$77,'Chi phí'!$G$78)-('Chi phí'!$J$5*'Chi phí'!$G$5+'Chi phí'!$J$6*'Chi phí'!$G$6)+E10 -> 7000000
A34: Theo khách chịu VAT (VND/khách) | B34: =CHOOSE(B$6,'Chi phí'!$H$77,'Chi phí'!$H$78) -> 0 | C34: =CHOOSE(C$6,'Chi phí'!$H$77,'Chi phí'!$H$78) -> 0 | D34: =CHOOSE(D$6,'Chi phí'!$H$77,'Chi phí'!$H$78) -> 0 | E34: =CHOOSE(E$6,'Chi phí'!$H$77,'Chi phí'!$H$78) -> 0
A35: Mừng từ người vắng mặt tính trên mỗi khách đến (VND) | B35: =(B9*0+(1-B8)/B8*'Giả định'!$B$21*'Giả định'!$B$22/B11) -> 15126.05 | C35: =(C9*0+(1-C8)/C8*'Giả định'!$B$21*'Giả định'!$B$22/C11) -> 15126.05 | D35: =(D9*0+(1-D8)/D8*'Giả định'!$B$21*'Giả định'!$B$22/D11) -> 15126.05 | E35: =(E9*0+(1-E8)/E8*'Giả định'!$B$21*'Giả định'!$B$22/E11) -> 15126.05
A37: Kiểm tra: cột B khớp với sheet Hòa vốn | B37: =IF(ABS(B16-'Hòa vốn'!B8)<1,"OK","LỆCH") -> OK
A38: Cách đọc: dòng 24 là mức mừng bình quân bạn phải THỰC SỰ nhận để không lỗ ở phương án đó. Nếu thấp hơn mức mừng bạn tin là có thể, phương án đó khả thi. Dòng 25 cho biết nếu giữ mức mừng, giá bàn phải xuống bao nhiêu.

Sheet Mô phỏng
A1: Bảng mô phỏng theo từng số khách đến (sheet phụ, không cần chỉnh)
A2: Mỗi dòng tính lại toàn bộ chi phí và doanh thu cho một số khách đến N, dựa trên sheet Giả định và Chi phí.
A4: Khách đến (N) | B4: Số bàn phải trả | C4: Chi phí chỉ phần tiệc (VND) | D4: Chi phí toàn bộ (VND) | E4: Doanh thu tiền mừng (VND) | F4: Lãi/(Lỗ) toàn bộ (VND) | G4: Lãi/(Lỗ) chỉ phần tiệc (VND) | H4: Cờ N không lỗ (toàn bộ) | I4: Cờ N còn lỗ (toàn bộ) | J4: Cờ N không lỗ (tiệc) | K4: Cờ N còn lỗ (tiệc)
A5: 0 | B5: =MAX('Giả định'!$B$9,ROUNDUP(A5/'Giả định'!$B$7,0)+'Giả định'!$B$8) -> 15 | C5: =('Chi phí'!$C$76+'Chi phí'!$D$76*B5+'Chi phí'!$E$76*A5+'Giả định'!$B$15*('Chi phí'!$F$76+'Chi phí'!$G$76*B5+'Chi phí'!$H$76*A5))*(1+'Giả định'!$B$16) -> 196295000 | D5: =('Chi phí'!$C$77+'Chi phí'!$D$77*B5+'Chi phí'!$E$77*A5+'Giả định'!$B$15*('Chi phí'!$F$77+'Chi phí'!$G$77*B5+'Chi phí'!$H$77*A5))*(1+'Giả định'!$B$16) -> 339900000 | E5: =A5/'Giả định'!$B$19*'Giả định'!$B$20+A5*'Giả định'!$B$23+'Giả định'!$B$24 -> 0 | F5: =E5-D5 -> -339900000 | G5: =E5-C5 -> -196295000 | H5: =IF(F5>=0,A5,"") | I5: =IF(F5<0,A5,0) -> 0 | J5: =IF(G5>=0,A5,"") | K5: =IF(G5<0,A5,0) -> 0
A6: =A5+1 -> 1 | B6: =MAX('Giả định'!$B$9,ROUNDUP(A6/'Giả định'!$B$7,0)+'Giả định'!$B$8) -> 15 | C6: =('Chi phí'!$C$76+'Chi phí'!$D$76*B6+'Chi phí'!$E$76*A6+'Giả định'!$B$15*('Chi phí'!$F$76+'Chi phí'!$G$76*B6+'Chi phí'!$H$76*A6))*(1+'Giả định'!$B$16) -> 196331740 | D6: =('Chi phí'!$C$77+'Chi phí'!$D$77*B6+'Chi phí'!$E$77*A6+'Giả định'!$B$15*('Chi phí'!$F$77+'Chi phí'!$G$77*B6+'Chi phí'!$H$77*A6))*(1+'Giả định'!$B$16) -> 339936740 | E6: =A6/'Giả định'!$B$19*'Giả định'!$B$20+A6*'Giả định'!$B$23+'Giả định'!$B$24 -> 372268.91 | F6: =E6-D6 -> -3.3956447e+08 | G6: =E6-C6 -> -1.9595947e+08 | H6: =IF(F6>=0,A6,"") | I6: =IF(F6<0,A6,0) -> 1 | J6: =IF(G6>=0,A6,"") | K6: =IF(G6<0,A6,0) -> 1
A7: =A6+1 -> 2 | B7: =MAX('Giả định'!$B$9,ROUNDUP(A7/'Giả định'!$B$7,0)+'Giả định'!$B$8) -> 15 | C7: =('Chi phí'!$C$76+'Chi phí'!$D$76*B7+'Chi phí'!$E$76*A7+'Giả định'!$B$15*('Chi phí'!$F$76+'Chi phí'!$G$76*B7+'Chi phí'!$H$76*A7))*(1+'Giả định'!$B$16) -> 196368480 | D7: =('Chi phí'!$C$77+'Chi phí'!$D$77*B7+'Chi phí'!$E$77*A7+'Giả định'!$B$15*('Chi phí'!$F$77+'Chi phí'!$G$77*B7+'Chi phí'!$H$77*A7))*(1+'Giả định'!$B$16) -> 339973480 | E7: =A7/'Giả định'!$B$19*'Giả định'!$B$20+A7*'Giả định'!$B$23+'Giả định'!$B$24 -> 744537.82 | F7: =E7-D7 -> -3.3922894e+08 | G7: =E7-C7 -> -1.9562394e+08 | H7: =IF(F7>=0,A7,"") | I7: =IF(F7<0,A7,0) -> 2 | J7: =IF(G7>=0,A7,"") | K7: =IF(G7<0,A7,0) -> 2
A8: =A7+1 -> 3 | B8: =MAX('Giả định'!$B$9,ROUNDUP(A8/'Giả định'!$B$7,0)+'Giả định'!$B$8) -> 15 | C8: =('Chi phí'!$C$76+'Chi phí'!$D$76*B8+'Chi phí'!$E$76*A8+'Giả định'!$B$15*('Chi phí'!$F$76+'Chi phí'!$G$76*B8+'Chi phí'!$H$76*A8))*(1+'Giả định'!$B$16) -> 196405220 | D8: =('Chi phí'!$C$77+'Chi phí'!$D$77*B8+'Chi phí'!$E$77*A8+'Giả định'!$B$15*('Chi phí'!$F$77+'Chi phí'!$G$77*B8+'Chi phí'!$H$77*A8))*(1+'Giả định'!$B$16) -> 340010220 | E8: =A8/'Giả định'!$B$19*'Giả định'!$B$20+A8*'Giả định'!$B$23+'Giả định'!$B$24 -> 1116806.7 | F8: =E8-D8 -> -3.3889341e+08 | G8: =E8-C8 -> -1.9528841e+08 | H8: =IF(F8>=0,A8,"") | I8: =IF(F8<0,A8,0) -> 3 | J8: =IF(G8>=0,A8,"") | K8: =IF(G8<0,A8,0) -> 3
A9: =A8+1 -> 4 | B9: =MAX('Giả định'!$B$9,ROUNDUP(A9/'Giả định'!$B$7,0)+'Giả định'!$B$8) -> 15 | C9: =('Chi phí'!$C$76+'Chi phí'!$D$76*B9+'Chi phí'!$E$76*A9+'Giả định'!$B$15*('Chi phí'!$F$76+'Chi phí'!$G$76*B9+'Chi phí'!$H$76*A9))*(1+'Giả định'!$B$16) -> 196441960 | D9: =('Chi phí'!$C$77+'Chi phí'!$D$77*B9+'Chi phí'!$E$77*A9+'Giả định'!$B$15*('Chi phí'!$F$77+'Chi phí'!$G$77*B9+'Chi phí'!$H$77*A9))*(1+'Giả định'!$B$16) -> 340046960 | E9: =A9/'Giả định'!$B$19*'Giả định'!$B$20+A9*'Giả định'!$B$23+'Giả định'!$B$24 -> 1489075.6 | F9: =E9-D9 -> -3.3855788e+08 | G9: =E9-C9 -> -1.9495288e+08 | H9: =IF(F9>=0,A9,"") | I9: =IF(F9<0,A9,0) -> 4 | J9: =IF(G9>=0,A9,"") | K9: =IF(G9<0,A9,0) -> 4
A10: =A9+1 -> 5 | B10: =MAX('Giả định'!$B$9,ROUNDUP(A10/'Giả định'!$B$7,0)+'Giả định'!$B$8) -> 15 | C10: =('Chi phí'!$C$76+'Chi phí'!$D$76*B10+'Chi phí'!$E$76*A10+'Giả định'!$B$15*('Chi phí'!$F$76+'Chi phí'!$G$76*B10+'Chi phí'!$H$76*A10))*(1+'Giả định'!$B$16) -> 196478700 | D10: =('Chi phí'!$C$77+'Chi phí'!$D$77*B10+'Chi phí'!$E$77*A10+'Giả định'!$B$15*('Chi phí'!$F$77+'Chi phí'!$G$77*B10+'Chi phí'!$H$77*A10))*(1+'Giả định'!$B$16) -> 340083700 | E10: =A10/'Giả định'!$B$19*'Giả định'!$B$20+A10*'Giả định'!$B$23+'Giả định'!$B$24 -> 1861344.5 | F10: =E10-D10 -> -3.3822236e+08 | G10: =E10-C10 -> -1.9461736e+08 | H10: =IF(F10>=0,A10,"") | I10: =IF(F10<0,A10,0) -> 5 | J10: =IF(G10>=0,A10,"") | K10: =IF(G10<0,A10,0) -> 5
A11: =A10+1 -> 6 | B11: =MAX('Giả định'!$B$9,ROUNDUP(A11/'Giả định'!$B$7,0)+'Giả định'!$B$8) -> 15 | C11: =('Chi phí'!$C$76+'Chi phí'!$D$76*B11+'Chi phí'!$E$76*A11+'Giả định'!$B$15*('Chi phí'!$F$76+'Chi phí'!$G$76*B11+'Chi phí'!$H$76*A11))*(1+'Giả định'!$B$16) -> 196515440 | D11: =('Chi phí'!$C$77+'Chi phí'!$D$77*B11+'Chi phí'!$E$77*A11+'Giả định'!$B$15*('Chi phí'!$F$77+'Chi phí'!$G$77*B11+'Chi phí'!$H$77*A11))*(1+'Giả định'!$B$16) -> 340120440 | E11: =A11/'Giả định'!$B$19*'Giả định'!$B$20+A11*'Giả định'!$B$23+'Giả định'!$B$24 -> 2233613.4 | F11: =E11-D11 -> -3.3788683e+08 | G11: =E11-C11 -> -1.9428183e+08 | H11: =IF(F11>=0,A11,"") | I11: =IF(F11<0,A11,0) -> 6 | J11: =IF(G11>=0,A11,"") | K11: =IF(G11<0,A11,0) -> 6
A12: =A11+1 -> 7 | B12: =MAX('Giả định'!$B$9,ROUNDUP(A12/'Giả định'!$B$7,0)+'Giả định'!$B$8) -> 15 | C12: =('Chi phí'!$C$76+'Chi phí'!$D$76*B12+'Chi phí'!$E$76*A12+'Giả định'!$B$15*('Chi phí'!$F$76+'Chi phí'!$G$76*B12+'Chi phí'!$H$76*A12))*(1+'Giả định'!$B$16) -> 196552180 | D12: =('Chi phí'!$C$77+'Chi phí'!$D$77*B12+'Chi phí'!$E$77*A12+'Giả định'!$B$15*('Chi phí'!$F$77+'Chi phí'!$G$77*B12+'Chi phí'!$H$77*A12))*(1+'Giả định'!$B$16) -> 340157180 | E12: =A12/'Giả định'!$B$19*'Giả định'!$B$20+A12*'Giả định'!$B$23+'Giả định'!$B$24 -> 2605882.4 | F12: =E12-D12 -> -3.375513e+08 | G12: =E12-C12 -> -1.939463e+08 | H12: =IF(F12>=0,A12,"") | I12: =IF(F12<0,A12,0) -> 7 | J12: =IF(G12>=0,A12,"") | K12: =IF(G12<0,A12,0) -> 7
A13: =A12+1 -> 8 | B13: =MAX('Giả định'!$B$9,ROUNDUP(A13/'Giả định'!$B$7,0)+'Giả định'!$B$8) -> 15 | C13: =('Chi phí'!$C$76+'Chi phí'!$D$76*B13+'Chi phí'!$E$76*A13+'Giả định'!$B$15*('Chi phí'!$F$76+'Chi phí'!$G$76*B13+'Chi phí'!$H$76*A13))*(1+'Giả định'!$B$16) -> 196588920 | D13: =('Chi phí'!$C$77+'Chi phí'!$D$77*B13+'Chi phí'!$E$77*A13+'Giả định'!$B$15*('Chi phí'!$F$77+'Chi phí'!$G$77*B13+'Chi phí'!$H$77*A13))*(1+'Giả định'!$B$16) -> 340193920 | E13: =A13/'Giả định'!$B$19*'Giả định'!$B$20+A13*'Giả định'!$B$23+'Giả định'!$B$24 -> 2978151.3 | F13: =E13-D13 -> -3.3721577e+08 | G13: =E13-C13 -> -1.9361077e+08 | H13: =IF(F13>=0,A13,"") | I13: =IF(F13<0,A13,0) -> 8 | J13: =IF(G13>=0,A13,"") | K13: =IF(G13<0,A13,0) -> 8
A14: =A13+1 -> 9 | B14: =MAX('Giả định'!$B$9,ROUNDUP(A14/'Giả định'!$B$7,0)+'Giả định'!$B$8) -> 15 | C14: =('Chi phí'!$C$76+'Chi phí'!$D$76*B14+'Chi phí'!$E$76*A14+'Giả định'!$B$15*('Chi phí'!$F$76+'Chi phí'!$G$76*B14+'Chi phí'!$H$76*A14))*(1+'Giả định'!$B$16) -> 196625660 | D14: =('Chi phí'!$C$77+'Chi phí'!$D$77*B14+'Chi phí'!$E$77*A14+'Giả định'!$B$15*('Chi phí'!$F$77+'Chi phí'!$G$77*B14+'Chi phí'!$H$77*A14))*(1+'Giả định'!$B$16) -> 340230660 | E14: =A14/'Giả định'!$B$19*'Giả định'!$B$20+A14*'Giả định'!$B$23+'Giả định'!$B$24 -> 3350420.2 | F14: =E14-D14 -> -3.3688024e+08 | G14: =E14-C14 -> -1.9327524e+08 | H14: =IF(F14>=0,A14,"") | I14: =IF(F14<0,A14,0) -> 9 | J14: =IF(G14>=0,A14,"") | K14: =IF(G14<0,A14,0) -> 9
A15: =A14+1 -> 10 | B15: =MAX('Giả định'!$B$9,ROUNDUP(A15/'Giả định'!$B$7,0)+'Giả định'!$B$8) -> 15 | C15: =('Chi phí'!$C$76+'Chi phí'!$D$76*B15+'Chi phí'!$E$76*A15+'Giả định'!$B$15*('Chi phí'!$F$76+'Chi phí'!$G$76*B15+'Chi phí'!$H$76*A15))*(1+'Giả định'!$B$16) -> 196662400 | D15: =('Chi phí'!$C$77+'Chi phí'!$D$77*B15+'Chi phí'!$E$77*A15+'Giả định'!$B$15*('Chi phí'!$F$77+'Chi phí'!$G$77*B15+'Chi phí'!$H$77*A15))*(1+'Giả định'!$B$16) -> 340267400 | E15: =A15/'Giả định'!$B$19*'Giả định'!$B$20+A15*'Giả định'!$B$23+'Giả định'!$B$24 -> 3722689.1 | F15: =E15-D15 -> -3.3654471e+08 | G15: =E15-C15 -> -1.9293971e+08 | H15: =IF(F15>=0,A15,"") | I15: =IF(F15<0,A15,0) -> 10 | J15: =IF(G15>=0,A15,"") | K15: =IF(G15<0,A15,0) -> 10
A16: =A15+1 -> 11 | B16: =MAX('Giả định'!$B$9,ROUNDUP(A16/'Giả định'!$B$7,0)+'Giả định'!$B$8) -> 15 | C16: =('Chi phí'!$C$76+'Chi phí'!$D$76*B16+'Chi phí'!$E$76*A16+'Giả định'!$B$15*('Chi phí'!$F$76+'Chi phí'!$G$76*B16+'Chi phí'!$H$76*A16))*(1+'Giả định'!$B$16) -> 196699140 | D16: =('Chi phí'!$C$77+'Chi phí'!$D$77*B16+'Chi phí'!$E$77*A16+'Giả định'!$B$15*('Chi phí'!$F$77+'Chi phí'!$G$77*B16+'Chi phí'!$H$77*A16))*(1+'Giả định'!$B$16) -> 340304140 | E16: =A16/'Giả định'!$B$19*'Giả định'!$B$20+A16*'Giả định'!$B$23+'Giả định'!$B$24 -> 4094958 | F16: =E16-D16 -> -3.3620918e+08 | G16: =E16-C16 -> -1.9260418e+08 | H16: =IF(F16>=0,A16,"") | I16: =IF(F16<0,A16,0) -> 11 | J16: =IF(G16>=0,A16,"") | K16: =IF(G16<0,A16,0) -> 11
A17: =A16+1 -> 12 | B17: =MAX('Giả định'!$B$9,ROUNDUP(A17/'Giả định'!$B$7,0)+'Giả định'!$B$8) -> 15 | C17: =('Chi phí'!$C$76+'Chi phí'!$D$76*B17+'Chi phí'!$E$76*A17+'Giả định'!$B$15*('Chi phí'!$F$76+'Chi phí'!$G$76*B17+'Chi phí'!$H$76*A17))*(1+'Giả định'!$B$16) -> 196735880 | D17: =('Chi phí'!$C$77+'Chi phí'!$D$77*B17+'Chi phí'!$E$77*A17+'Giả định'!$B$15*('Chi phí'!$F$77+'Chi phí'!$G$77*B17+'Chi phí'!$H$77*A17))*(1+'Giả định'!$B$16) -> 340340880 | E17: =A17/'Giả định'!$B$19*'Giả định'!$B$20+A17*'Giả định'!$B$23+'Giả định'!$B$24 -> 4467226.9 | F17: =E17-D17 -> -3.3587365e+08 | G17: =E17-C17 -> -1.9226865e+08 | H17: =IF(F17>=0,A17,"") | I17: =IF(F17<0,A17,0) -> 12 | J17: =IF(G17>=0,A17,"") | K17: =IF(G17<0,A17,0) -> 12
... A1005: =A1004+1 -> 1000 | B1005: =MAX('Giả định'!$B$9,ROUNDUP(A1005/'Giả định'!$B$7,0)+'Giả định'!$B$8) -> 101 | C1005: =('Chi phí'!$C$76+'Chi phí'!$D$76*B1005+'Chi phí'!$E$76*A1005+'Giả định'!$B$15*('Chi phí'!$F$76+'Chi phí'!$G$76*B1005+'Chi phí'!$H$76*A1005))*(1+'Giả định'!$B$16) -> 1021999000 | D1005: =('Chi phí'!$C$77+'Chi phí'!$D$77*B1005+'Chi phí'!$E$77*A1005+'Giả định'!$B$15*('Chi phí'!$F$77+'Chi phí'!$G$77*B1005+'Chi phí'!$H$77*A1005))*(1+'Giả định'!$B$16) -> 1165604000 | E1005: =A1005/'Giả định'!$B$19*'Giả định'!$B$20+A1005*'Giả định'!$B$23+'Giả định'!$B$24 -> 3.7226891e+08 | F1005: =E1005-D1005 -> -7.9333509e+08 | G1005: =E1005-C1005 -> -6.4973009e+08 | H1005: =IF(F1005>=0,A1005,"") | I1005: =IF(F1005<0,A1005,0) -> 1000 | J1005: =IF(G1005>=0,A1005,"") | K1005: =IF(G1005<0,A1005,0) -> 1000
